2017-06-17 21:43:10,415 -> my_app -> INFO -> `Creating` an instance of auxiliary.Auxiliary
2017-06-17 21:43:10,416 -> my_app.auxiliary.Auxiliary -> INFO -> creating an instance of Auxiliary
2017-06-17 21:43:10,416 -> my_app -> INFO -> `Created` an instance of auxiliary.Auxiliary
2017-06-17 21:43:10,416 -> my_app -> INFO -> `Calling` auxiliary.Auxiliary.do_something
2017-06-17 21:43:10,416 -> my_app.auxiliary.Auxiliary -> INFO -> doing something
2017-06-17 21:43:10,416 -> my_app.auxiliary.Auxiliary -> INFO -> done doing something
2017-06-17 21:43:10,416 -> my_app -> INFO -> `Finished` auxiliary.Auxiliary.do_something
2017-06-17 21:43:10,416 -> my_app -> INFO -> `Calling` auxiliary.Auxiliary.something_function()
2017-06-17 21:43:10,416 -> my_app.auxiliary -> INFO -> received a call to "some_function"
2017-06-17 21:43:10,416 -> my_app -> INFO -> `Done` with auxiliary.some_function()
2017-06-17 21:43:10,416 -> my_app -> ERROR -> This is error log for test
